<?xml version='1.0' encoding='utf-8'?>
<sdf version="1.5">
  <model name="cable">
    <static>false</static>
    <self_collide>true</self_collide>
    <link name="link_0">
      <gravity>true</gravity>
      <pose>0 0 0 0 0 0</pose>
      <collision name="link_0_collision">
        <geometry>
          <box>
            <size>0.02 0.005 0.005</size>
          </box>
        </geometry>
      </collision>
      <visual name="link_0_visual">
        <geometry>
          <box>
            <size>0.02 0.005 0.005</size>
          </box>
        </geometry>
      </visual>
    </link>
    <joint name="joint_0_world" type="fixed">
      <pose>0 0 0 0 0 0</pose>
      <child>link_0</child>
      <parent>world</parent>
    </joint>
    <link name="link_1">
      <gravity>true</gravity>
      <pose>0.02 0 0 0 0 0</pose>
      <collision name="link_1_collision">
        <geometry>
          <box>
            <size>0.02 0.005 0.005</size>
          </box>
        </geometry>
      </collision>
      <visual name="link_1_visual">
        <geometry>
          <box>
            <size>0.02 0.005 0.005</size>
          </box>
        </geometry>
      </visual>
    </link>
    <joint type="ball" name="joint_0_1">
      <pose>-0.01 0 0 0 0 0</pose>
      <child>link_1</child>
      <parent>link_0</parent>
    </joint>
    <link name="link_2">
      <gravity>true</gravity>
      <pose>0.04 0 0 0 0 0</pose>
      <collision name="link_2_collision">
        <geometry>
          <box>
            <size>0.02 0.005 0.005</size>
          </box>
        </geometry>
      </collision>
      <visual name="link_2_visual">
        <geometry>
          <box>
            <size>0.02 0.005 0.005</size>
          </box>
        </geometry>
      </visual>
    </link>
    <joint type="ball" name="joint_1_2">
      <pose>-0.01 0 0 0 0 0</pose>
      <child>link_2</child>
      <parent>link_1</parent>
    </joint>
    <link name="link_3">
      <gravity>true</gravity>
      <pose>0.06 0 0 0 0 0</pose>
      <collision name="link_3_collision">
        <geometry>
          <box>
            <size>0.02 0.005 0.005</size>
          </box>
        </geometry>
      </collision>
      <visual name="link_3_visual">
        <geometry>
          <box>
            <size>0.02 0.005 0.005</size>
          </box>
        </geometry>
      </visual>
    </link>
    <joint type="ball" name="joint_2_3">
      <pose>-0.01 0 0 0 0 0</pose>
      <child>link_3</child>
      <parent>link_2</parent>
    </joint>
    <link name="link_4">
      <gravity>true</gravity>
      <pose>0.08 0 0 0 0 0</pose>
      <collision name="link_4_collision">
        <geometry>
          <box>
            <size>0.02 0.005 0.005</size>
          </box>
        </geometry>
      </collision>
      <visual name="link_4_visual">
        <geometry>
          <box>
            <size>0.02 0.005 0.005</size>
          </box>
        </geometry>
      </visual>
    </link>
    <joint type="ball" name="joint_3_4">
      <pose>-0.01 0 0 0 0 0</pose>
      <child>link_4</child>
      <parent>link_3</parent>
    </joint>
    <link name="link_5">
      <gravity>true</gravity>
      <pose>0.1 0 0 0 0 0</pose>
      <collision name="link_5_collision">
        <geometry>
          <box>
            <size>0.02 0.005 0.005</size>
          </box>
        </geometry>
      </collision>
      <visual name="link_5_visual">
        <geometry>
          <box>
            <size>0.02 0.005 0.005</size>
          </box>
        </geometry>
      </visual>
    </link>
    <joint type="ball" name="joint_4_5">
      <pose>-0.01 0 0 0 0 0</pose>
      <child>link_5</child>
      <parent>link_4</parent>
    </joint>
    <link name="link_6">
      <gravity>true</gravity>
      <pose>0.12 0 0 0 0 0</pose>
      <collision name="link_6_collision">
        <geometry>
          <box>
            <size>0.02 0.005 0.005</size>
          </box>
        </geometry>
      </collision>
      <visual name="link_6_visual">
        <geometry>
          <box>
            <size>0.02 0.005 0.005</size>
          </box>
        </geometry>
      </visual>
    </link>
    <joint type="ball" name="joint_5_6">
      <pose>-0.01 0 0 0 0 0</pose>
      <child>link_6</child>
      <parent>link_5</parent>
    </joint>
    <link name="link_7">
      <gravity>true</gravity>
      <pose>0.14 0 0 0 0 0</pose>
      <collision name="link_7_collision">
        <geometry>
          <box>
            <size>0.02 0.005 0.005</size>
          </box>
        </geometry>
      </collision>
      <visual name="link_7_visual">
        <geometry>
          <box>
            <size>0.02 0.005 0.005</size>
          </box>
        </geometry>
      </visual>
    </link>
    <joint type="ball" name="joint_6_7">
      <pose>-0.01 0 0 0 0 0</pose>
      <child>link_7</child>
      <parent>link_6</parent>
    </joint>
    <link name="link_8">
      <gravity>true</gravity>
      <pose>0.16 0 0 0 0 0</pose>
      <collision name="link_8_collision">
        <geometry>
          <box>
            <size>0.02 0.005 0.005</size>
          </box>
        </geometry>
      </collision>
      <visual name="link_8_visual">
        <geometry>
          <box>
            <size>0.02 0.005 0.005</size>
          </box>
        </geometry>
      </visual>
    </link>
    <joint type="ball" name="joint_7_8">
      <pose>-0.01 0 0 0 0 0</pose>
      <child>link_8</child>
      <parent>link_7</parent>
    </joint>
    <link name="link_9">
      <gravity>true</gravity>
      <pose>0.18 0 0 0 0 0</pose>
      <collision name="link_9_collision">
        <geometry>
          <box>
            <size>0.02 0.005 0.005</size>
          </box>
        </geometry>
      </collision>
      <visual name="link_9_visual">
        <geometry>
          <box>
            <size>0.02 0.005 0.005</size>
          </box>
        </geometry>
      </visual>
    </link>
    <joint type="ball" name="joint_8_9">
      <pose>-0.01 0 0 0 0 0</pose>
      <child>link_9</child>
      <parent>link_8</parent>
    </joint>
    <link name="link_10">
      <gravity>true</gravity>
      <pose>0.2 0 0 0 0 0</pose>
      <collision name="link_10_collision">
        <geometry>
          <box>
            <size>0.02 0.005 0.005</size>
          </box>
        </geometry>
      </collision>
      <visual name="link_10_visual">
        <geometry>
          <box>
            <size>0.02 0.005 0.005</size>
          </box>
        </geometry>
      </visual>
    </link>
    <joint type="ball" name="joint_9_10">
      <pose>-0.01 0 0 0 0 0</pose>
      <child>link_10</child>
      <parent>link_9</parent>
    </joint>
    <link name="link_11">
      <gravity>true</gravity>
      <pose>0.22 0 0 0 0 0</pose>
      <collision name="link_11_collision">
        <geometry>
          <box>
            <size>0.02 0.005 0.005</size>
          </box>
        </geometry>
      </collision>
      <visual name="link_11_visual">
        <geometry>
          <box>
            <size>0.02 0.005 0.005</size>
          </box>
        </geometry>
      </visual>
    </link>
    <joint type="ball" name="joint_10_11">
      <pose>-0.01 0 0 0 0 0</pose>
      <child>link_11</child>
      <parent>link_10</parent>
    </joint>
    <link name="link_12">
      <gravity>true</gravity>
      <pose>0.24 0 0 0 0 0</pose>
      <collision name="link_12_collision">
        <geometry>
          <box>
            <size>0.02 0.005 0.005</size>
          </box>
        </geometry>
      </collision>
      <visual name="link_12_visual">
        <geometry>
          <box>
            <size>0.02 0.005 0.005</size>
          </box>
        </geometry>
      </visual>
    </link>
    <joint type="ball" name="joint_11_12">
      <pose>-0.01 0 0 0 0 0</pose>
      <child>link_12</child>
      <parent>link_11</parent>
    </joint>
    <link name="link_13">
      <gravity>true</gravity>
      <pose>0.26 0 0 0 0 0</pose>
      <collision name="link_13_collision">
        <geometry>
          <box>
            <size>0.02 0.005 0.005</size>
          </box>
        </geometry>
      </collision>
      <visual name="link_13_visual">
        <geometry>
          <box>
            <size>0.02 0.005 0.005</size>
          </box>
        </geometry>
      </visual>
    </link>
    <joint type="ball" name="joint_12_13">
      <pose>-0.01 0 0 0 0 0</pose>
      <child>link_13</child>
      <parent>link_12</parent>
    </joint>
    <link name="link_14">
      <gravity>true</gravity>
      <pose>0.28 0 0 0 0 0</pose>
      <collision name="link_14_collision">
        <geometry>
          <box>
            <size>0.02 0.005 0.005</size>
          </box>
        </geometry>
      </collision>
      <visual name="link_14_visual">
        <geometry>
          <box>
            <size>0.02 0.005 0.005</size>
          </box>
        </geometry>
      </visual>
    </link>
    <joint type="ball" name="joint_13_14">
      <pose>-0.01 0 0 0 0 0</pose>
      <child>link_14</child>
      <parent>link_13</parent>
    </joint>
    <link name="link_15">
      <gravity>true</gravity>
      <pose>0.3 0 0 0 0 0</pose>
      <collision name="link_15_collision">
        <geometry>
          <box>
            <size>0.02 0.005 0.005</size>
          </box>
        </geometry>
      </collision>
      <visual name="link_15_visual">
        <geometry>
          <box>
            <size>0.02 0.005 0.005</size>
          </box>
        </geometry>
      </visual>
    </link>
    <joint type="ball" name="joint_14_15">
      <pose>-0.01 0 0 0 0 0</pose>
      <child>link_15</child>
      <parent>link_14</parent>
    </joint>
    <link name="link_16">
      <gravity>true</gravity>
      <pose>0.32 0 0 0 0 0</pose>
      <collision name="link_16_collision">
        <geometry>
          <box>
            <size>0.02 0.005 0.005</size>
          </box>
        </geometry>
      </collision>
      <visual name="link_16_visual">
        <geometry>
          <box>
            <size>0.02 0.005 0.005</size>
          </box>
        </geometry>
      </visual>
    </link>
    <joint type="ball" name="joint_15_16">
      <pose>-0.01 0 0 0 0 0</pose>
      <child>link_16</child>
      <parent>link_15</parent>
    </joint>
    <link name="link_17">
      <gravity>true</gravity>
      <pose>0.34 0 0 0 0 0</pose>
      <collision name="link_17_collision">
        <geometry>
          <box>
            <size>0.02 0.005 0.005</size>
          </box>
        </geometry>
      </collision>
      <visual name="link_17_visual">
        <geometry>
          <box>
            <size>0.02 0.005 0.005</size>
          </box>
        </geometry>
      </visual>
    </link>
    <joint type="ball" name="joint_16_17">
      <pose>-0.01 0 0 0 0 0</pose>
      <child>link_17</child>
      <parent>link_16</parent>
    </joint>
    <link name="link_18">
      <gravity>true</gravity>
      <pose>0.36 0 0 0 0 0</pose>
      <collision name="link_18_collision">
        <geometry>
          <box>
            <size>0.02 0.005 0.005</size>
          </box>
        </geometry>
      </collision>
      <visual name="link_18_visual">
        <geometry>
          <box>
            <size>0.02 0.005 0.005</size>
          </box>
        </geometry>
      </visual>
    </link>
    <joint type="ball" name="joint_17_18">
      <pose>-0.01 0 0 0 0 0</pose>
      <child>link_18</child>
      <parent>link_17</parent>
    </joint>
    <link name="link_19">
      <gravity>true</gravity>
      <pose>0.38 0 0 0 0 0</pose>
      <collision name="link_19_collision">
        <geometry>
          <box>
            <size>0.02 0.005 0.005</size>
          </box>
        </geometry>
      </collision>
      <visual name="link_19_visual">
        <geometry>
          <box>
            <size>0.02 0.005 0.005</size>
          </box>
        </geometry>
      </visual>
    </link>
    <joint type="ball" name="joint_18_19">
      <pose>-0.01 0 0 0 0 0</pose>
      <child>link_19</child>
      <parent>link_18</parent>
    </joint>
  </model>
</sdf>