<?xml version='1.0' encoding='utf-8'?>
<sdf version="1.5">
  <model name="cable">
    <static>false</static>
    <self_collide>true</self_collide>
    <link name="link_0">
      <gravity>true</gravity>
      <pose>0 0 0 0 0 0</pose>
      <inertial>
        <mass>0.028148670176164552</mass>
        <inertia>
          <ixx>3.518583772020569e-07</ixx>
          <ixy>0</ixy>
          <ixz>0</ixz>
          <iyy>3.929085212089636e-06</iyy>
          <iyz>0</iyz>
          <izz>3.929085212089636e-06</izz>
        </inertia>
      </inertial>
      <collision name="link_0_collision">
        <geometry>
          <box>
            <size>0.04 0.01 0.01</size>
          </box>
        </geometry>
      </collision>
      <visual name="link_0_visual">
        <geometry>
          <box>
            <size>0.04 0.01 0.01</size>
          </box>
        </geometry>
      </visual>
    </link>
    <joint name="joint_0_world" type="fixed">
      <pose>0 0 0 0 0 0</pose>
      <child>link_0</child>
      <parent>world</parent>
    </joint>
    <link name="link_1">
      <gravity>true</gravity>
      <pose>0.04 0 0 0 0 0</pose>
      <inertial>
        <mass>0.028148670176164552</mass>
        <inertia>
          <ixx>3.518583772020569e-07</ixx>
          <ixy>0</ixy>
          <ixz>0</ixz>
          <iyy>3.929085212089636e-06</iyy>
          <iyz>0</iyz>
          <izz>3.929085212089636e-06</izz>
        </inertia>
      </inertial>
      <collision name="link_1_collision">
        <geometry>
          <box>
            <size>0.04 0.01 0.01</size>
          </box>
        </geometry>
      </collision>
      <visual name="link_1_visual">
        <geometry>
          <box>
            <size>0.04 0.01 0.01</size>
          </box>
        </geometry>
      </visual>
    </link>
    <joint type="ball" name="joint_0_1">
      <pose>-0.02 0 0 0 0 0</pose>
      <child>link_1</child>
      <parent>link_0</parent>
      <axis>
        <dynamics>
          <damping>10</damping>
          <friction>5</friction>
        </dynamics>
      </axis>
      <axis>
        <dynamics>
          <damping>10</damping>
          <friction>5</friction>
        </dynamics>
      </axis>
    </joint>
    <link name="link_2">
      <gravity>true</gravity>
      <pose>0.08 0 0 0 0 0</pose>
      <inertial>
        <mass>0.028148670176164552</mass>
        <inertia>
          <ixx>3.518583772020569e-07</ixx>
          <ixy>0</ixy>
          <ixz>0</ixz>
          <iyy>3.929085212089636e-06</iyy>
          <iyz>0</iyz>
          <izz>3.929085212089636e-06</izz>
        </inertia>
      </inertial>
      <collision name="link_2_collision">
        <geometry>
          <box>
            <size>0.04 0.01 0.01</size>
          </box>
        </geometry>
      </collision>
      <visual name="link_2_visual">
        <geometry>
          <box>
            <size>0.04 0.01 0.01</size>
          </box>
        </geometry>
      </visual>
    </link>
    <joint type="ball" name="joint_1_2">
      <pose>-0.02 0 0 0 0 0</pose>
      <child>link_2</child>
      <parent>link_1</parent>
      <axis>
        <dynamics>
          <damping>10</damping>
          <friction>5</friction>
        </dynamics>
      </axis>
      <axis>
        <dynamics>
          <damping>10</damping>
          <friction>5</friction>
        </dynamics>
      </axis>
    </joint>
    <link name="link_3">
      <gravity>true</gravity>
      <pose>0.12 0 0 0 0 0</pose>
      <inertial>
        <mass>0.028148670176164552</mass>
        <inertia>
          <ixx>3.518583772020569e-07</ixx>
          <ixy>0</ixy>
          <ixz>0</ixz>
          <iyy>3.929085212089636e-06</iyy>
          <iyz>0</iyz>
          <izz>3.929085212089636e-06</izz>
        </inertia>
      </inertial>
      <collision name="link_3_collision">
        <geometry>
          <box>
            <size>0.04 0.01 0.01</size>
          </box>
        </geometry>
      </collision>
      <visual name="link_3_visual">
        <geometry>
          <box>
            <size>0.04 0.01 0.01</size>
          </box>
        </geometry>
      </visual>
    </link>
    <joint type="ball" name="joint_2_3">
      <pose>-0.02 0 0 0 0 0</pose>
      <child>link_3</child>
      <parent>link_2</parent>
      <axis>
        <dynamics>
          <damping>10</damping>
          <friction>5</friction>
        </dynamics>
      </axis>
      <axis>
        <dynamics>
          <damping>10</damping>
          <friction>5</friction>
        </dynamics>
      </axis>
    </joint>
    <link name="link_4">
      <gravity>true</gravity>
      <pose>0.16 0 0 0 0 0</pose>
      <inertial>
        <mass>0.028148670176164552</mass>
        <inertia>
          <ixx>3.518583772020569e-07</ixx>
          <ixy>0</ixy>
          <ixz>0</ixz>
          <iyy>3.929085212089636e-06</iyy>
          <iyz>0</iyz>
          <izz>3.929085212089636e-06</izz>
        </inertia>
      </inertial>
      <collision name="link_4_collision">
        <geometry>
          <box>
            <size>0.04 0.01 0.01</size>
          </box>
        </geometry>
      </collision>
      <visual name="link_4_visual">
        <geometry>
          <box>
            <size>0.04 0.01 0.01</size>
          </box>
        </geometry>
      </visual>
    </link>
    <joint type="ball" name="joint_3_4">
      <pose>-0.02 0 0 0 0 0</pose>
      <child>link_4</child>
      <parent>link_3</parent>
      <axis>
        <dynamics>
          <damping>10</damping>
          <friction>5</friction>
        </dynamics>
      </axis>
      <axis>
        <dynamics>
          <damping>10</damping>
          <friction>5</friction>
        </dynamics>
      </axis>
    </joint>
    <link name="link_5">
      <gravity>true</gravity>
      <pose>0.2 0 0 0 0 0</pose>
      <inertial>
        <mass>0.028148670176164552</mass>
        <inertia>
          <ixx>3.518583772020569e-07</ixx>
          <ixy>0</ixy>
          <ixz>0</ixz>
          <iyy>3.929085212089636e-06</iyy>
          <iyz>0</iyz>
          <izz>3.929085212089636e-06</izz>
        </inertia>
      </inertial>
      <collision name="link_5_collision">
        <geometry>
          <box>
            <size>0.04 0.01 0.01</size>
          </box>
        </geometry>
      </collision>
      <visual name="link_5_visual">
        <geometry>
          <box>
            <size>0.04 0.01 0.01</size>
          </box>
        </geometry>
      </visual>
    </link>
    <joint type="ball" name="joint_4_5">
      <pose>-0.02 0 0 0 0 0</pose>
      <child>link_5</child>
      <parent>link_4</parent>
      <axis>
        <dynamics>
          <damping>10</damping>
          <friction>5</friction>
        </dynamics>
      </axis>
      <axis>
        <dynamics>
          <damping>10</damping>
          <friction>5</friction>
        </dynamics>
      </axis>
    </joint>
    <link name="link_6">
      <gravity>true</gravity>
      <pose>0.24 0 0 0 0 0</pose>
      <inertial>
        <mass>0.028148670176164552</mass>
        <inertia>
          <ixx>3.518583772020569e-07</ixx>
          <ixy>0</ixy>
          <ixz>0</ixz>
          <iyy>3.929085212089636e-06</iyy>
          <iyz>0</iyz>
          <izz>3.929085212089636e-06</izz>
        </inertia>
      </inertial>
      <collision name="link_6_collision">
        <geometry>
          <box>
            <size>0.04 0.01 0.01</size>
          </box>
        </geometry>
      </collision>
      <visual name="link_6_visual">
        <geometry>
          <box>
            <size>0.04 0.01 0.01</size>
          </box>
        </geometry>
      </visual>
    </link>
    <joint type="ball" name="joint_5_6">
      <pose>-0.02 0 0 0 0 0</pose>
      <child>link_6</child>
      <parent>link_5</parent>
      <axis>
        <dynamics>
          <damping>10</damping>
          <friction>5</friction>
        </dynamics>
      </axis>
      <axis>
        <dynamics>
          <damping>10</damping>
          <friction>5</friction>
        </dynamics>
      </axis>
    </joint>
    <link name="link_7">
      <gravity>true</gravity>
      <pose>0.28 0 0 0 0 0</pose>
      <inertial>
        <mass>0.028148670176164552</mass>
        <inertia>
          <ixx>3.518583772020569e-07</ixx>
          <ixy>0</ixy>
          <ixz>0</ixz>
          <iyy>3.929085212089636e-06</iyy>
          <iyz>0</iyz>
          <izz>3.929085212089636e-06</izz>
        </inertia>
      </inertial>
      <collision name="link_7_collision">
        <geometry>
          <box>
            <size>0.04 0.01 0.01</size>
          </box>
        </geometry>
      </collision>
      <visual name="link_7_visual">
        <geometry>
          <box>
            <size>0.04 0.01 0.01</size>
          </box>
        </geometry>
      </visual>
    </link>
    <joint type="ball" name="joint_6_7">
      <pose>-0.02 0 0 0 0 0</pose>
      <child>link_7</child>
      <parent>link_6</parent>
      <axis>
        <dynamics>
          <damping>10</damping>
          <friction>5</friction>
        </dynamics>
      </axis>
      <axis>
        <dynamics>
          <damping>10</damping>
          <friction>5</friction>
        </dynamics>
      </axis>
    </joint>
    <link name="link_8">
      <gravity>true</gravity>
      <pose>0.32 0 0 0 0 0</pose>
      <inertial>
        <mass>0.028148670176164552</mass>
        <inertia>
          <ixx>3.518583772020569e-07</ixx>
          <ixy>0</ixy>
          <ixz>0</ixz>
          <iyy>3.929085212089636e-06</iyy>
          <iyz>0</iyz>
          <izz>3.929085212089636e-06</izz>
        </inertia>
      </inertial>
      <collision name="link_8_collision">
        <geometry>
          <box>
            <size>0.04 0.01 0.01</size>
          </box>
        </geometry>
      </collision>
      <visual name="link_8_visual">
        <geometry>
          <box>
            <size>0.04 0.01 0.01</size>
          </box>
        </geometry>
      </visual>
    </link>
    <joint type="ball" name="joint_7_8">
      <pose>-0.02 0 0 0 0 0</pose>
      <child>link_8</child>
      <parent>link_7</parent>
      <axis>
        <dynamics>
          <damping>10</damping>
          <friction>5</friction>
        </dynamics>
      </axis>
      <axis>
        <dynamics>
          <damping>10</damping>
          <friction>5</friction>
        </dynamics>
      </axis>
    </joint>
    <link name="link_9">
      <gravity>true</gravity>
      <pose>0.36 0 0 0 0 0</pose>
      <inertial>
        <mass>0.028148670176164552</mass>
        <inertia>
          <ixx>3.518583772020569e-07</ixx>
          <ixy>0</ixy>
          <ixz>0</ixz>
          <iyy>3.929085212089636e-06</iyy>
          <iyz>0</iyz>
          <izz>3.929085212089636e-06</izz>
        </inertia>
      </inertial>
      <collision name="link_9_collision">
        <geometry>
          <box>
            <size>0.04 0.01 0.01</size>
          </box>
        </geometry>
      </collision>
      <visual name="link_9_visual">
        <geometry>
          <box>
            <size>0.04 0.01 0.01</size>
          </box>
        </geometry>
      </visual>
    </link>
    <joint type="ball" name="joint_8_9">
      <pose>-0.02 0 0 0 0 0</pose>
      <child>link_9</child>
      <parent>link_8</parent>
      <axis>
        <dynamics>
          <damping>10</damping>
          <friction>5</friction>
        </dynamics>
      </axis>
      <axis>
        <dynamics>
          <damping>10</damping>
          <friction>5</friction>
        </dynamics>
      </axis>
    </joint>
    <link name="link_10">
      <gravity>true</gravity>
      <pose>0.4 0 0 0 0 0</pose>
      <inertial>
        <mass>0.028148670176164552</mass>
        <inertia>
          <ixx>3.518583772020569e-07</ixx>
          <ixy>0</ixy>
          <ixz>0</ixz>
          <iyy>3.929085212089636e-06</iyy>
          <iyz>0</iyz>
          <izz>3.929085212089636e-06</izz>
        </inertia>
      </inertial>
      <collision name="link_10_collision">
        <geometry>
          <box>
            <size>0.04 0.01 0.01</size>
          </box>
        </geometry>
      </collision>
      <visual name="link_10_visual">
        <geometry>
          <box>
            <size>0.04 0.01 0.01</size>
          </box>
        </geometry>
      </visual>
    </link>
    <joint type="ball" name="joint_9_10">
      <pose>-0.02 0 0 0 0 0</pose>
      <child>link_10</child>
      <parent>link_9</parent>
      <axis>
        <dynamics>
          <damping>10</damping>
          <friction>5</friction>
        </dynamics>
      </axis>
      <axis>
        <dynamics>
          <damping>10</damping>
          <friction>5</friction>
        </dynamics>
      </axis>
    </joint>
    <link name="link_11">
      <gravity>true</gravity>
      <pose>0.44 0 0 0 0 0</pose>
      <inertial>
        <mass>0.028148670176164552</mass>
        <inertia>
          <ixx>3.518583772020569e-07</ixx>
          <ixy>0</ixy>
          <ixz>0</ixz>
          <iyy>3.929085212089636e-06</iyy>
          <iyz>0</iyz>
          <izz>3.929085212089636e-06</izz>
        </inertia>
      </inertial>
      <collision name="link_11_collision">
        <geometry>
          <box>
            <size>0.04 0.01 0.01</size>
          </box>
        </geometry>
      </collision>
      <visual name="link_11_visual">
        <geometry>
          <box>
            <size>0.04 0.01 0.01</size>
          </box>
        </geometry>
      </visual>
    </link>
    <joint type="ball" name="joint_10_11">
      <pose>-0.02 0 0 0 0 0</pose>
      <child>link_11</child>
      <parent>link_10</parent>
      <axis>
        <dynamics>
          <damping>10</damping>
          <friction>5</friction>
        </dynamics>
      </axis>
      <axis>
        <dynamics>
          <damping>10</damping>
          <friction>5</friction>
        </dynamics>
      </axis>
    </joint>
    <link name="link_12">
      <gravity>true</gravity>
      <pose>0.48 0 0 0 0 0</pose>
      <inertial>
        <mass>0.028148670176164552</mass>
        <inertia>
          <ixx>3.518583772020569e-07</ixx>
          <ixy>0</ixy>
          <ixz>0</ixz>
          <iyy>3.929085212089636e-06</iyy>
          <iyz>0</iyz>
          <izz>3.929085212089636e-06</izz>
        </inertia>
      </inertial>
      <collision name="link_12_collision">
        <geometry>
          <box>
            <size>0.04 0.01 0.01</size>
          </box>
        </geometry>
      </collision>
      <visual name="link_12_visual">
        <geometry>
          <box>
            <size>0.04 0.01 0.01</size>
          </box>
        </geometry>
      </visual>
    </link>
    <joint type="ball" name="joint_11_12">
      <pose>-0.02 0 0 0 0 0</pose>
      <child>link_12</child>
      <parent>link_11</parent>
      <axis>
        <dynamics>
          <damping>10</damping>
          <friction>5</friction>
        </dynamics>
      </axis>
      <axis>
        <dynamics>
          <damping>10</damping>
          <friction>5</friction>
        </dynamics>
      </axis>
    </joint>
    <link name="link_13">
      <gravity>true</gravity>
      <pose>0.52 0 0 0 0 0</pose>
      <inertial>
        <mass>0.028148670176164552</mass>
        <inertia>
          <ixx>3.518583772020569e-07</ixx>
          <ixy>0</ixy>
          <ixz>0</ixz>
          <iyy>3.929085212089636e-06</iyy>
          <iyz>0</iyz>
          <izz>3.929085212089636e-06</izz>
        </inertia>
      </inertial>
      <collision name="link_13_collision">
        <geometry>
          <box>
            <size>0.04 0.01 0.01</size>
          </box>
        </geometry>
      </collision>
      <visual name="link_13_visual">
        <geometry>
          <box>
            <size>0.04 0.01 0.01</size>
          </box>
        </geometry>
      </visual>
    </link>
    <joint type="ball" name="joint_12_13">
      <pose>-0.02 0 0 0 0 0</pose>
      <child>link_13</child>
      <parent>link_12</parent>
      <axis>
        <dynamics>
          <damping>10</damping>
          <friction>5</friction>
        </dynamics>
      </axis>
      <axis>
        <dynamics>
          <damping>10</damping>
          <friction>5</friction>
        </dynamics>
      </axis>
    </joint>
    <link name="link_14">
      <gravity>true</gravity>
      <pose>0.56 0 0 0 0 0</pose>
      <inertial>
        <mass>0.028148670176164552</mass>
        <inertia>
          <ixx>3.518583772020569e-07</ixx>
          <ixy>0</ixy>
          <ixz>0</ixz>
          <iyy>3.929085212089636e-06</iyy>
          <iyz>0</iyz>
          <izz>3.929085212089636e-06</izz>
        </inertia>
      </inertial>
      <collision name="link_14_collision">
        <geometry>
          <box>
            <size>0.04 0.01 0.01</size>
          </box>
        </geometry>
      </collision>
      <visual name="link_14_visual">
        <geometry>
          <box>
            <size>0.04 0.01 0.01</size>
          </box>
        </geometry>
      </visual>
    </link>
    <joint type="ball" name="joint_13_14">
      <pose>-0.02 0 0 0 0 0</pose>
      <child>link_14</child>
      <parent>link_13</parent>
      <axis>
        <dynamics>
          <damping>10</damping>
          <friction>5</friction>
        </dynamics>
      </axis>
      <axis>
        <dynamics>
          <damping>10</damping>
          <friction>5</friction>
        </dynamics>
      </axis>
    </joint>
    <link name="link_15">
      <gravity>true</gravity>
      <pose>0.6 0 0 0 0 0</pose>
      <inertial>
        <mass>0.028148670176164552</mass>
        <inertia>
          <ixx>3.518583772020569e-07</ixx>
          <ixy>0</ixy>
          <ixz>0</ixz>
          <iyy>3.929085212089636e-06</iyy>
          <iyz>0</iyz>
          <izz>3.929085212089636e-06</izz>
        </inertia>
      </inertial>
      <collision name="link_15_collision">
        <geometry>
          <box>
            <size>0.04 0.01 0.01</size>
          </box>
        </geometry>
      </collision>
      <visual name="link_15_visual">
        <geometry>
          <box>
            <size>0.04 0.01 0.01</size>
          </box>
        </geometry>
      </visual>
    </link>
    <joint type="ball" name="joint_14_15">
      <pose>-0.02 0 0 0 0 0</pose>
      <child>link_15</child>
      <parent>link_14</parent>
      <axis>
        <dynamics>
          <damping>10</damping>
          <friction>5</friction>
        </dynamics>
      </axis>
      <axis>
        <dynamics>
          <damping>10</damping>
          <friction>5</friction>
        </dynamics>
      </axis>
    </joint>
    <link name="link_16">
      <gravity>true</gravity>
      <pose>0.64 0 0 0 0 0</pose>
      <inertial>
        <mass>0.028148670176164552</mass>
        <inertia>
          <ixx>3.518583772020569e-07</ixx>
          <ixy>0</ixy>
          <ixz>0</ixz>
          <iyy>3.929085212089636e-06</iyy>
          <iyz>0</iyz>
          <izz>3.929085212089636e-06</izz>
        </inertia>
      </inertial>
      <collision name="link_16_collision">
        <geometry>
          <box>
            <size>0.04 0.01 0.01</size>
          </box>
        </geometry>
      </collision>
      <visual name="link_16_visual">
        <geometry>
          <box>
            <size>0.04 0.01 0.01</size>
          </box>
        </geometry>
      </visual>
    </link>
    <joint type="ball" name="joint_15_16">
      <pose>-0.02 0 0 0 0 0</pose>
      <child>link_16</child>
      <parent>link_15</parent>
      <axis>
        <dynamics>
          <damping>10</damping>
          <friction>5</friction>
        </dynamics>
      </axis>
      <axis>
        <dynamics>
          <damping>10</damping>
          <friction>5</friction>
        </dynamics>
      </axis>
    </joint>
    <link name="link_17">
      <gravity>true</gravity>
      <pose>0.68 0 0 0 0 0</pose>
      <inertial>
        <mass>0.028148670176164552</mass>
        <inertia>
          <ixx>3.518583772020569e-07</ixx>
          <ixy>0</ixy>
          <ixz>0</ixz>
          <iyy>3.929085212089636e-06</iyy>
          <iyz>0</iyz>
          <izz>3.929085212089636e-06</izz>
        </inertia>
      </inertial>
      <collision name="link_17_collision">
        <geometry>
          <box>
            <size>0.04 0.01 0.01</size>
          </box>
        </geometry>
      </collision>
      <visual name="link_17_visual">
        <geometry>
          <box>
            <size>0.04 0.01 0.01</size>
          </box>
        </geometry>
      </visual>
    </link>
    <joint type="ball" name="joint_16_17">
      <pose>-0.02 0 0 0 0 0</pose>
      <child>link_17</child>
      <parent>link_16</parent>
      <axis>
        <dynamics>
          <damping>10</damping>
          <friction>5</friction>
        </dynamics>
      </axis>
      <axis>
        <dynamics>
          <damping>10</damping>
          <friction>5</friction>
        </dynamics>
      </axis>
    </joint>
    <link name="link_18">
      <gravity>true</gravity>
      <pose>0.72 0 0 0 0 0</pose>
      <inertial>
        <mass>0.028148670176164552</mass>
        <inertia>
          <ixx>3.518583772020569e-07</ixx>
          <ixy>0</ixy>
          <ixz>0</ixz>
          <iyy>3.929085212089636e-06</iyy>
          <iyz>0</iyz>
          <izz>3.929085212089636e-06</izz>
        </inertia>
      </inertial>
      <collision name="link_18_collision">
        <geometry>
          <box>
            <size>0.04 0.01 0.01</size>
          </box>
        </geometry>
      </collision>
      <visual name="link_18_visual">
        <geometry>
          <box>
            <size>0.04 0.01 0.01</size>
          </box>
        </geometry>
      </visual>
    </link>
    <joint type="ball" name="joint_17_18">
      <pose>-0.02 0 0 0 0 0</pose>
      <child>link_18</child>
      <parent>link_17</parent>
      <axis>
        <dynamics>
          <damping>10</damping>
          <friction>5</friction>
        </dynamics>
      </axis>
      <axis>
        <dynamics>
          <damping>10</damping>
          <friction>5</friction>
        </dynamics>
      </axis>
    </joint>
    <link name="link_19">
      <gravity>true</gravity>
      <pose>0.76 0 0 0 0 0</pose>
      <inertial>
        <mass>0.028148670176164552</mass>
        <inertia>
          <ixx>3.518583772020569e-07</ixx>
          <ixy>0</ixy>
          <ixz>0</ixz>
          <iyy>3.929085212089636e-06</iyy>
          <iyz>0</iyz>
          <izz>3.929085212089636e-06</izz>
        </inertia>
      </inertial>
      <collision name="link_19_collision">
        <geometry>
          <box>
            <size>0.04 0.01 0.01</size>
          </box>
        </geometry>
      </collision>
      <visual name="link_19_visual">
        <geometry>
          <box>
            <size>0.04 0.01 0.01</size>
          </box>
        </geometry>
      </visual>
    </link>
    <joint type="ball" name="joint_18_19">
      <pose>-0.02 0 0 0 0 0</pose>
      <child>link_19</child>
      <parent>link_18</parent>
      <axis>
        <dynamics>
          <damping>10</damping>
          <friction>5</friction>
        </dynamics>
      </axis>
      <axis>
        <dynamics>
          <damping>10</damping>
          <friction>5</friction>
        </dynamics>
      </axis>
    </joint>
    <link name="link_20">
      <gravity>true</gravity>
      <pose>0.8 0 0 0 0 0</pose>
      <inertial>
        <mass>0.028148670176164552</mass>
        <inertia>
          <ixx>3.518583772020569e-07</ixx>
          <ixy>0</ixy>
          <ixz>0</ixz>
          <iyy>3.929085212089636e-06</iyy>
          <iyz>0</iyz>
          <izz>3.929085212089636e-06</izz>
        </inertia>
      </inertial>
      <collision name="link_20_collision">
        <geometry>
          <box>
            <size>0.04 0.01 0.01</size>
          </box>
        </geometry>
      </collision>
      <visual name="link_20_visual">
        <geometry>
          <box>
            <size>0.04 0.01 0.01</size>
          </box>
        </geometry>
      </visual>
    </link>
    <joint type="ball" name="joint_19_20">
      <pose>-0.02 0 0 0 0 0</pose>
      <child>link_20</child>
      <parent>link_19</parent>
      <axis>
        <dynamics>
          <damping>10</damping>
          <friction>5</friction>
        </dynamics>
      </axis>
      <axis>
        <dynamics>
          <damping>10</damping>
          <friction>5</friction>
        </dynamics>
      </axis>
    </joint>
    <link name="link_21">
      <gravity>true</gravity>
      <pose>0.84 0 0 0 0 0</pose>
      <inertial>
        <mass>0.028148670176164552</mass>
        <inertia>
          <ixx>3.518583772020569e-07</ixx>
          <ixy>0</ixy>
          <ixz>0</ixz>
          <iyy>3.929085212089636e-06</iyy>
          <iyz>0</iyz>
          <izz>3.929085212089636e-06</izz>
        </inertia>
      </inertial>
      <collision name="link_21_collision">
        <geometry>
          <box>
            <size>0.04 0.01 0.01</size>
          </box>
        </geometry>
      </collision>
      <visual name="link_21_visual">
        <geometry>
          <box>
            <size>0.04 0.01 0.01</size>
          </box>
        </geometry>
      </visual>
    </link>
    <joint type="ball" name="joint_20_21">
      <pose>-0.02 0 0 0 0 0</pose>
      <child>link_21</child>
      <parent>link_20</parent>
      <axis>
        <dynamics>
          <damping>10</damping>
          <friction>5</friction>
        </dynamics>
      </axis>
      <axis>
        <dynamics>
          <damping>10</damping>
          <friction>5</friction>
        </dynamics>
      </axis>
    </joint>
    <link name="link_22">
      <gravity>true</gravity>
      <pose>0.88 0 0 0 0 0</pose>
      <inertial>
        <mass>0.028148670176164552</mass>
        <inertia>
          <ixx>3.518583772020569e-07</ixx>
          <ixy>0</ixy>
          <ixz>0</ixz>
          <iyy>3.929085212089636e-06</iyy>
          <iyz>0</iyz>
          <izz>3.929085212089636e-06</izz>
        </inertia>
      </inertial>
      <collision name="link_22_collision">
        <geometry>
          <box>
            <size>0.04 0.01 0.01</size>
          </box>
        </geometry>
      </collision>
      <visual name="link_22_visual">
        <geometry>
          <box>
            <size>0.04 0.01 0.01</size>
          </box>
        </geometry>
      </visual>
    </link>
    <joint type="ball" name="joint_21_22">
      <pose>-0.02 0 0 0 0 0</pose>
      <child>link_22</child>
      <parent>link_21</parent>
      <axis>
        <dynamics>
          <damping>10</damping>
          <friction>5</friction>
        </dynamics>
      </axis>
      <axis>
        <dynamics>
          <damping>10</damping>
          <friction>5</friction>
        </dynamics>
      </axis>
    </joint>
    <link name="link_23">
      <gravity>true</gravity>
      <pose>0.92 0 0 0 0 0</pose>
      <inertial>
        <mass>0.028148670176164552</mass>
        <inertia>
          <ixx>3.518583772020569e-07</ixx>
          <ixy>0</ixy>
          <ixz>0</ixz>
          <iyy>3.929085212089636e-06</iyy>
          <iyz>0</iyz>
          <izz>3.929085212089636e-06</izz>
        </inertia>
      </inertial>
      <collision name="link_23_collision">
        <geometry>
          <box>
            <size>0.04 0.01 0.01</size>
          </box>
        </geometry>
      </collision>
      <visual name="link_23_visual">
        <geometry>
          <box>
            <size>0.04 0.01 0.01</size>
          </box>
        </geometry>
      </visual>
    </link>
    <joint type="ball" name="joint_22_23">
      <pose>-0.02 0 0 0 0 0</pose>
      <child>link_23</child>
      <parent>link_22</parent>
      <axis>
        <dynamics>
          <damping>10</damping>
          <friction>5</friction>
        </dynamics>
      </axis>
      <axis>
        <dynamics>
          <damping>10</damping>
          <friction>5</friction>
        </dynamics>
      </axis>
    </joint>
    <link name="link_24">
      <gravity>true</gravity>
      <pose>0.96 0 0 0 0 0</pose>
      <inertial>
        <mass>0.028148670176164552</mass>
        <inertia>
          <ixx>3.518583772020569e-07</ixx>
          <ixy>0</ixy>
          <ixz>0</ixz>
          <iyy>3.929085212089636e-06</iyy>
          <iyz>0</iyz>
          <izz>3.929085212089636e-06</izz>
        </inertia>
      </inertial>
      <collision name="link_24_collision">
        <geometry>
          <box>
            <size>0.04 0.01 0.01</size>
          </box>
        </geometry>
      </collision>
      <visual name="link_24_visual">
        <geometry>
          <box>
            <size>0.04 0.01 0.01</size>
          </box>
        </geometry>
      </visual>
    </link>
    <joint type="ball" name="joint_23_24">
      <pose>-0.02 0 0 0 0 0</pose>
      <child>link_24</child>
      <parent>link_23</parent>
      <axis>
        <dynamics>
          <damping>10</damping>
          <friction>5</friction>
        </dynamics>
      </axis>
      <axis>
        <dynamics>
          <damping>10</damping>
          <friction>5</friction>
        </dynamics>
      </axis>
    </joint>
    <link name="link_25">
      <gravity>true</gravity>
      <pose>1.0 0 0 0 0 0</pose>
      <inertial>
        <mass>0.028148670176164552</mass>
        <inertia>
          <ixx>3.518583772020569e-07</ixx>
          <ixy>0</ixy>
          <ixz>0</ixz>
          <iyy>3.929085212089636e-06</iyy>
          <iyz>0</iyz>
          <izz>3.929085212089636e-06</izz>
        </inertia>
      </inertial>
      <collision name="link_25_collision">
        <geometry>
          <box>
            <size>0.04 0.01 0.01</size>
          </box>
        </geometry>
      </collision>
      <visual name="link_25_visual">
        <geometry>
          <box>
            <size>0.04 0.01 0.01</size>
          </box>
        </geometry>
      </visual>
    </link>
    <joint type="ball" name="joint_24_25">
      <pose>-0.02 0 0 0 0 0</pose>
      <child>link_25</child>
      <parent>link_24</parent>
      <axis>
        <dynamics>
          <damping>10</damping>
          <friction>5</friction>
        </dynamics>
      </axis>
      <axis>
        <dynamics>
          <damping>10</damping>
          <friction>5</friction>
        </dynamics>
      </axis>
    </joint>
    <link name="link_26">
      <gravity>true</gravity>
      <pose>1.04 0 0 0 0 0</pose>
      <inertial>
        <mass>0.028148670176164552</mass>
        <inertia>
          <ixx>3.518583772020569e-07</ixx>
          <ixy>0</ixy>
          <ixz>0</ixz>
          <iyy>3.929085212089636e-06</iyy>
          <iyz>0</iyz>
          <izz>3.929085212089636e-06</izz>
        </inertia>
      </inertial>
      <collision name="link_26_collision">
        <geometry>
          <box>
            <size>0.04 0.01 0.01</size>
          </box>
        </geometry>
      </collision>
      <visual name="link_26_visual">
        <geometry>
          <box>
            <size>0.04 0.01 0.01</size>
          </box>
        </geometry>
      </visual>
    </link>
    <joint type="ball" name="joint_25_26">
      <pose>-0.02 0 0 0 0 0</pose>
      <child>link_26</child>
      <parent>link_25</parent>
      <axis>
        <dynamics>
          <damping>10</damping>
          <friction>5</friction>
        </dynamics>
      </axis>
      <axis>
        <dynamics>
          <damping>10</damping>
          <friction>5</friction>
        </dynamics>
      </axis>
    </joint>
    <link name="link_27">
      <gravity>true</gravity>
      <pose>1.08 0 0 0 0 0</pose>
      <inertial>
        <mass>0.028148670176164552</mass>
        <inertia>
          <ixx>3.518583772020569e-07</ixx>
          <ixy>0</ixy>
          <ixz>0</ixz>
          <iyy>3.929085212089636e-06</iyy>
          <iyz>0</iyz>
          <izz>3.929085212089636e-06</izz>
        </inertia>
      </inertial>
      <collision name="link_27_collision">
        <geometry>
          <box>
            <size>0.04 0.01 0.01</size>
          </box>
        </geometry>
      </collision>
      <visual name="link_27_visual">
        <geometry>
          <box>
            <size>0.04 0.01 0.01</size>
          </box>
        </geometry>
      </visual>
    </link>
    <joint type="ball" name="joint_26_27">
      <pose>-0.02 0 0 0 0 0</pose>
      <child>link_27</child>
      <parent>link_26</parent>
      <axis>
        <dynamics>
          <damping>10</damping>
          <friction>5</friction>
        </dynamics>
      </axis>
      <axis>
        <dynamics>
          <damping>10</damping>
          <friction>5</friction>
        </dynamics>
      </axis>
    </joint>
    <link name="link_28">
      <gravity>true</gravity>
      <pose>1.12 0 0 0 0 0</pose>
      <inertial>
        <mass>0.028148670176164552</mass>
        <inertia>
          <ixx>3.518583772020569e-07</ixx>
          <ixy>0</ixy>
          <ixz>0</ixz>
          <iyy>3.929085212089636e-06</iyy>
          <iyz>0</iyz>
          <izz>3.929085212089636e-06</izz>
        </inertia>
      </inertial>
      <collision name="link_28_collision">
        <geometry>
          <box>
            <size>0.04 0.01 0.01</size>
          </box>
        </geometry>
      </collision>
      <visual name="link_28_visual">
        <geometry>
          <box>
            <size>0.04 0.01 0.01</size>
          </box>
        </geometry>
      </visual>
    </link>
    <joint type="ball" name="joint_27_28">
      <pose>-0.02 0 0 0 0 0</pose>
      <child>link_28</child>
      <parent>link_27</parent>
      <axis>
        <dynamics>
          <damping>10</damping>
          <friction>5</friction>
        </dynamics>
      </axis>
      <axis>
        <dynamics>
          <damping>10</damping>
          <friction>5</friction>
        </dynamics>
      </axis>
    </joint>
    <link name="link_29">
      <gravity>true</gravity>
      <pose>1.16 0 0 0 0 0</pose>
      <inertial>
        <mass>0.028148670176164552</mass>
        <inertia>
          <ixx>3.518583772020569e-07</ixx>
          <ixy>0</ixy>
          <ixz>0</ixz>
          <iyy>3.929085212089636e-06</iyy>
          <iyz>0</iyz>
          <izz>3.929085212089636e-06</izz>
        </inertia>
      </inertial>
      <collision name="link_29_collision">
        <geometry>
          <box>
            <size>0.04 0.01 0.01</size>
          </box>
        </geometry>
      </collision>
      <visual name="link_29_visual">
        <geometry>
          <box>
            <size>0.04 0.01 0.01</size>
          </box>
        </geometry>
      </visual>
    </link>
    <joint type="ball" name="joint_28_29">
      <pose>-0.02 0 0 0 0 0</pose>
      <child>link_29</child>
      <parent>link_28</parent>
      <axis>
        <dynamics>
          <damping>10</damping>
          <friction>5</friction>
        </dynamics>
      </axis>
      <axis>
        <dynamics>
          <damping>10</damping>
          <friction>5</friction>
        </dynamics>
      </axis>
    </joint>
    <link name="link_30">
      <gravity>true</gravity>
      <pose>1.2 0 0 0 0 0</pose>
      <inertial>
        <mass>0.028148670176164552</mass>
        <inertia>
          <ixx>3.518583772020569e-07</ixx>
          <ixy>0</ixy>
          <ixz>0</ixz>
          <iyy>3.929085212089636e-06</iyy>
          <iyz>0</iyz>
          <izz>3.929085212089636e-06</izz>
        </inertia>
      </inertial>
      <collision name="link_30_collision">
        <geometry>
          <box>
            <size>0.04 0.01 0.01</size>
          </box>
        </geometry>
      </collision>
      <visual name="link_30_visual">
        <geometry>
          <box>
            <size>0.04 0.01 0.01</size>
          </box>
        </geometry>
      </visual>
    </link>
    <joint type="ball" name="joint_29_30">
      <pose>-0.02 0 0 0 0 0</pose>
      <child>link_30</child>
      <parent>link_29</parent>
      <axis>
        <dynamics>
          <damping>10</damping>
          <friction>5</friction>
        </dynamics>
      </axis>
      <axis>
        <dynamics>
          <damping>10</damping>
          <friction>5</friction>
        </dynamics>
      </axis>
    </joint>
    <link name="link_31">
      <gravity>true</gravity>
      <pose>1.24 0 0 0 0 0</pose>
      <inertial>
        <mass>0.028148670176164552</mass>
        <inertia>
          <ixx>3.518583772020569e-07</ixx>
          <ixy>0</ixy>
          <ixz>0</ixz>
          <iyy>3.929085212089636e-06</iyy>
          <iyz>0</iyz>
          <izz>3.929085212089636e-06</izz>
        </inertia>
      </inertial>
      <collision name="link_31_collision">
        <geometry>
          <box>
            <size>0.04 0.01 0.01</size>
          </box>
        </geometry>
      </collision>
      <visual name="link_31_visual">
        <geometry>
          <box>
            <size>0.04 0.01 0.01</size>
          </box>
        </geometry>
      </visual>
    </link>
    <joint type="ball" name="joint_30_31">
      <pose>-0.02 0 0 0 0 0</pose>
      <child>link_31</child>
      <parent>link_30</parent>
      <axis>
        <dynamics>
          <damping>10</damping>
          <friction>5</friction>
        </dynamics>
      </axis>
      <axis>
        <dynamics>
          <damping>10</damping>
          <friction>5</friction>
        </dynamics>
      </axis>
    </joint>
    <link name="link_32">
      <gravity>true</gravity>
      <pose>1.28 0 0 0 0 0</pose>
      <inertial>
        <mass>0.028148670176164552</mass>
        <inertia>
          <ixx>3.518583772020569e-07</ixx>
          <ixy>0</ixy>
          <ixz>0</ixz>
          <iyy>3.929085212089636e-06</iyy>
          <iyz>0</iyz>
          <izz>3.929085212089636e-06</izz>
        </inertia>
      </inertial>
      <collision name="link_32_collision">
        <geometry>
          <box>
            <size>0.04 0.01 0.01</size>
          </box>
        </geometry>
      </collision>
      <visual name="link_32_visual">
        <geometry>
          <box>
            <size>0.04 0.01 0.01</size>
          </box>
        </geometry>
      </visual>
    </link>
    <joint type="ball" name="joint_31_32">
      <pose>-0.02 0 0 0 0 0</pose>
      <child>link_32</child>
      <parent>link_31</parent>
      <axis>
        <dynamics>
          <damping>10</damping>
          <friction>5</friction>
        </dynamics>
      </axis>
      <axis>
        <dynamics>
          <damping>10</damping>
          <friction>5</friction>
        </dynamics>
      </axis>
    </joint>
    <link name="link_33">
      <gravity>true</gravity>
      <pose>1.32 0 0 0 0 0</pose>
      <inertial>
        <mass>0.028148670176164552</mass>
        <inertia>
          <ixx>3.518583772020569e-07</ixx>
          <ixy>0</ixy>
          <ixz>0</ixz>
          <iyy>3.929085212089636e-06</iyy>
          <iyz>0</iyz>
          <izz>3.929085212089636e-06</izz>
        </inertia>
      </inertial>
      <collision name="link_33_collision">
        <geometry>
          <box>
            <size>0.04 0.01 0.01</size>
          </box>
        </geometry>
      </collision>
      <visual name="link_33_visual">
        <geometry>
          <box>
            <size>0.04 0.01 0.01</size>
          </box>
        </geometry>
      </visual>
    </link>
    <joint type="ball" name="joint_32_33">
      <pose>-0.02 0 0 0 0 0</pose>
      <child>link_33</child>
      <parent>link_32</parent>
      <axis>
        <dynamics>
          <damping>10</damping>
          <friction>5</friction>
        </dynamics>
      </axis>
      <axis>
        <dynamics>
          <damping>10</damping>
          <friction>5</friction>
        </dynamics>
      </axis>
    </joint>
    <link name="link_34">
      <gravity>true</gravity>
      <pose>1.36 0 0 0 0 0</pose>
      <inertial>
        <mass>0.028148670176164552</mass>
        <inertia>
          <ixx>3.518583772020569e-07</ixx>
          <ixy>0</ixy>
          <ixz>0</ixz>
          <iyy>3.929085212089636e-06</iyy>
          <iyz>0</iyz>
          <izz>3.929085212089636e-06</izz>
        </inertia>
      </inertial>
      <collision name="link_34_collision">
        <geometry>
          <box>
            <size>0.04 0.01 0.01</size>
          </box>
        </geometry>
      </collision>
      <visual name="link_34_visual">
        <geometry>
          <box>
            <size>0.04 0.01 0.01</size>
          </box>
        </geometry>
      </visual>
    </link>
    <joint type="ball" name="joint_33_34">
      <pose>-0.02 0 0 0 0 0</pose>
      <child>link_34</child>
      <parent>link_33</parent>
      <axis>
        <dynamics>
          <damping>10</damping>
          <friction>5</friction>
        </dynamics>
      </axis>
      <axis>
        <dynamics>
          <damping>10</damping>
          <friction>5</friction>
        </dynamics>
      </axis>
    </joint>
    <link name="link_35">
      <gravity>true</gravity>
      <pose>1.4000000000000001 0 0 0 0 0</pose>
      <inertial>
        <mass>0.028148670176164552</mass>
        <inertia>
          <ixx>3.518583772020569e-07</ixx>
          <ixy>0</ixy>
          <ixz>0</ixz>
          <iyy>3.929085212089636e-06</iyy>
          <iyz>0</iyz>
          <izz>3.929085212089636e-06</izz>
        </inertia>
      </inertial>
      <collision name="link_35_collision">
        <geometry>
          <box>
            <size>0.04 0.01 0.01</size>
          </box>
        </geometry>
      </collision>
      <visual name="link_35_visual">
        <geometry>
          <box>
            <size>0.04 0.01 0.01</size>
          </box>
        </geometry>
      </visual>
    </link>
    <joint type="ball" name="joint_34_35">
      <pose>-0.02 0 0 0 0 0</pose>
      <child>link_35</child>
      <parent>link_34</parent>
      <axis>
        <dynamics>
          <damping>10</damping>
          <friction>5</friction>
        </dynamics>
      </axis>
      <axis>
        <dynamics>
          <damping>10</damping>
          <friction>5</friction>
        </dynamics>
      </axis>
    </joint>
    <link name="link_36">
      <gravity>true</gravity>
      <pose>1.44 0 0 0 0 0</pose>
      <inertial>
        <mass>0.028148670176164552</mass>
        <inertia>
          <ixx>3.518583772020569e-07</ixx>
          <ixy>0</ixy>
          <ixz>0</ixz>
          <iyy>3.929085212089636e-06</iyy>
          <iyz>0</iyz>
          <izz>3.929085212089636e-06</izz>
        </inertia>
      </inertial>
      <collision name="link_36_collision">
        <geometry>
          <box>
            <size>0.04 0.01 0.01</size>
          </box>
        </geometry>
      </collision>
      <visual name="link_36_visual">
        <geometry>
          <box>
            <size>0.04 0.01 0.01</size>
          </box>
        </geometry>
      </visual>
    </link>
    <joint type="ball" name="joint_35_36">
      <pose>-0.02 0 0 0 0 0</pose>
      <child>link_36</child>
      <parent>link_35</parent>
      <axis>
        <dynamics>
          <damping>10</damping>
          <friction>5</friction>
        </dynamics>
      </axis>
      <axis>
        <dynamics>
          <damping>10</damping>
          <friction>5</friction>
        </dynamics>
      </axis>
    </joint>
    <link name="link_37">
      <gravity>true</gravity>
      <pose>1.48 0 0 0 0 0</pose>
      <inertial>
        <mass>0.028148670176164552</mass>
        <inertia>
          <ixx>3.518583772020569e-07</ixx>
          <ixy>0</ixy>
          <ixz>0</ixz>
          <iyy>3.929085212089636e-06</iyy>
          <iyz>0</iyz>
          <izz>3.929085212089636e-06</izz>
        </inertia>
      </inertial>
      <collision name="link_37_collision">
        <geometry>
          <box>
            <size>0.04 0.01 0.01</size>
          </box>
        </geometry>
      </collision>
      <visual name="link_37_visual">
        <geometry>
          <box>
            <size>0.04 0.01 0.01</size>
          </box>
        </geometry>
      </visual>
    </link>
    <joint type="ball" name="joint_36_37">
      <pose>-0.02 0 0 0 0 0</pose>
      <child>link_37</child>
      <parent>link_36</parent>
      <axis>
        <dynamics>
          <damping>10</damping>
          <friction>5</friction>
        </dynamics>
      </axis>
      <axis>
        <dynamics>
          <damping>10</damping>
          <friction>5</friction>
        </dynamics>
      </axis>
    </joint>
    <link name="link_38">
      <gravity>true</gravity>
      <pose>1.52 0 0 0 0 0</pose>
      <inertial>
        <mass>0.028148670176164552</mass>
        <inertia>
          <ixx>3.518583772020569e-07</ixx>
          <ixy>0</ixy>
          <ixz>0</ixz>
          <iyy>3.929085212089636e-06</iyy>
          <iyz>0</iyz>
          <izz>3.929085212089636e-06</izz>
        </inertia>
      </inertial>
      <collision name="link_38_collision">
        <geometry>
          <box>
            <size>0.04 0.01 0.01</size>
          </box>
        </geometry>
      </collision>
      <visual name="link_38_visual">
        <geometry>
          <box>
            <size>0.04 0.01 0.01</size>
          </box>
        </geometry>
      </visual>
    </link>
    <joint type="ball" name="joint_37_38">
      <pose>-0.02 0 0 0 0 0</pose>
      <child>link_38</child>
      <parent>link_37</parent>
      <axis>
        <dynamics>
          <damping>10</damping>
          <friction>5</friction>
        </dynamics>
      </axis>
      <axis>
        <dynamics>
          <damping>10</damping>
          <friction>5</friction>
        </dynamics>
      </axis>
    </joint>
    <link name="link_39">
      <gravity>true</gravity>
      <pose>1.56 0 0 0 0 0</pose>
      <inertial>
        <mass>0.028148670176164552</mass>
        <inertia>
          <ixx>3.518583772020569e-07</ixx>
          <ixy>0</ixy>
          <ixz>0</ixz>
          <iyy>3.929085212089636e-06</iyy>
          <iyz>0</iyz>
          <izz>3.929085212089636e-06</izz>
        </inertia>
      </inertial>
      <collision name="link_39_collision">
        <geometry>
          <box>
            <size>0.04 0.01 0.01</size>
          </box>
        </geometry>
      </collision>
      <visual name="link_39_visual">
        <geometry>
          <box>
            <size>0.04 0.01 0.01</size>
          </box>
        </geometry>
      </visual>
    </link>
    <joint type="ball" name="joint_38_39">
      <pose>-0.02 0 0 0 0 0</pose>
      <child>link_39</child>
      <parent>link_38</parent>
      <axis>
        <dynamics>
          <damping>10</damping>
          <friction>5</friction>
        </dynamics>
      </axis>
      <axis>
        <dynamics>
          <damping>10</damping>
          <friction>5</friction>
        </dynamics>
      </axis>
    </joint>
    <link name="link_40">
      <gravity>true</gravity>
      <pose>1.6 0 0 0 0 0</pose>
      <inertial>
        <mass>0.028148670176164552</mass>
        <inertia>
          <ixx>3.518583772020569e-07</ixx>
          <ixy>0</ixy>
          <ixz>0</ixz>
          <iyy>3.929085212089636e-06</iyy>
          <iyz>0</iyz>
          <izz>3.929085212089636e-06</izz>
        </inertia>
      </inertial>
      <collision name="link_40_collision">
        <geometry>
          <box>
            <size>0.04 0.01 0.01</size>
          </box>
        </geometry>
      </collision>
      <visual name="link_40_visual">
        <geometry>
          <box>
            <size>0.04 0.01 0.01</size>
          </box>
        </geometry>
      </visual>
    </link>
    <joint type="ball" name="joint_39_40">
      <pose>-0.02 0 0 0 0 0</pose>
      <child>link_40</child>
      <parent>link_39</parent>
      <axis>
        <dynamics>
          <damping>10</damping>
          <friction>5</friction>
        </dynamics>
      </axis>
      <axis>
        <dynamics>
          <damping>10</damping>
          <friction>5</friction>
        </dynamics>
      </axis>
    </joint>
    <link name="link_41">
      <gravity>true</gravity>
      <pose>1.6400000000000001 0 0 0 0 0</pose>
      <inertial>
        <mass>0.028148670176164552</mass>
        <inertia>
          <ixx>3.518583772020569e-07</ixx>
          <ixy>0</ixy>
          <ixz>0</ixz>
          <iyy>3.929085212089636e-06</iyy>
          <iyz>0</iyz>
          <izz>3.929085212089636e-06</izz>
        </inertia>
      </inertial>
      <collision name="link_41_collision">
        <geometry>
          <box>
            <size>0.04 0.01 0.01</size>
          </box>
        </geometry>
      </collision>
      <visual name="link_41_visual">
        <geometry>
          <box>
            <size>0.04 0.01 0.01</size>
          </box>
        </geometry>
      </visual>
    </link>
    <joint type="ball" name="joint_40_41">
      <pose>-0.02 0 0 0 0 0</pose>
      <child>link_41</child>
      <parent>link_40</parent>
      <axis>
        <dynamics>
          <damping>10</damping>
          <friction>5</friction>
        </dynamics>
      </axis>
      <axis>
        <dynamics>
          <damping>10</damping>
          <friction>5</friction>
        </dynamics>
      </axis>
    </joint>
    <link name="link_42">
      <gravity>true</gravity>
      <pose>1.68 0 0 0 0 0</pose>
      <inertial>
        <mass>0.028148670176164552</mass>
        <inertia>
          <ixx>3.518583772020569e-07</ixx>
          <ixy>0</ixy>
          <ixz>0</ixz>
          <iyy>3.929085212089636e-06</iyy>
          <iyz>0</iyz>
          <izz>3.929085212089636e-06</izz>
        </inertia>
      </inertial>
      <collision name="link_42_collision">
        <geometry>
          <box>
            <size>0.04 0.01 0.01</size>
          </box>
        </geometry>
      </collision>
      <visual name="link_42_visual">
        <geometry>
          <box>
            <size>0.04 0.01 0.01</size>
          </box>
        </geometry>
      </visual>
    </link>
    <joint type="ball" name="joint_41_42">
      <pose>-0.02 0 0 0 0 0</pose>
      <child>link_42</child>
      <parent>link_41</parent>
      <axis>
        <dynamics>
          <damping>10</damping>
          <friction>5</friction>
        </dynamics>
      </axis>
      <axis>
        <dynamics>
          <damping>10</damping>
          <friction>5</friction>
        </dynamics>
      </axis>
    </joint>
    <link name="link_43">
      <gravity>true</gravity>
      <pose>1.72 0 0 0 0 0</pose>
      <inertial>
        <mass>0.028148670176164552</mass>
        <inertia>
          <ixx>3.518583772020569e-07</ixx>
          <ixy>0</ixy>
          <ixz>0</ixz>
          <iyy>3.929085212089636e-06</iyy>
          <iyz>0</iyz>
          <izz>3.929085212089636e-06</izz>
        </inertia>
      </inertial>
      <collision name="link_43_collision">
        <geometry>
          <box>
            <size>0.04 0.01 0.01</size>
          </box>
        </geometry>
      </collision>
      <visual name="link_43_visual">
        <geometry>
          <box>
            <size>0.04 0.01 0.01</size>
          </box>
        </geometry>
      </visual>
    </link>
    <joint type="ball" name="joint_42_43">
      <pose>-0.02 0 0 0 0 0</pose>
      <child>link_43</child>
      <parent>link_42</parent>
      <axis>
        <dynamics>
          <damping>10</damping>
          <friction>5</friction>
        </dynamics>
      </axis>
      <axis>
        <dynamics>
          <damping>10</damping>
          <friction>5</friction>
        </dynamics>
      </axis>
    </joint>
    <link name="link_44">
      <gravity>true</gravity>
      <pose>1.76 0 0 0 0 0</pose>
      <inertial>
        <mass>0.028148670176164552</mass>
        <inertia>
          <ixx>3.518583772020569e-07</ixx>
          <ixy>0</ixy>
          <ixz>0</ixz>
          <iyy>3.929085212089636e-06</iyy>
          <iyz>0</iyz>
          <izz>3.929085212089636e-06</izz>
        </inertia>
      </inertial>
      <collision name="link_44_collision">
        <geometry>
          <box>
            <size>0.04 0.01 0.01</size>
          </box>
        </geometry>
      </collision>
      <visual name="link_44_visual">
        <geometry>
          <box>
            <size>0.04 0.01 0.01</size>
          </box>
        </geometry>
      </visual>
    </link>
    <joint type="ball" name="joint_43_44">
      <pose>-0.02 0 0 0 0 0</pose>
      <child>link_44</child>
      <parent>link_43</parent>
      <axis>
        <dynamics>
          <damping>10</damping>
          <friction>5</friction>
        </dynamics>
      </axis>
      <axis>
        <dynamics>
          <damping>10</damping>
          <friction>5</friction>
        </dynamics>
      </axis>
    </joint>
    <link name="link_45">
      <gravity>true</gravity>
      <pose>1.8 0 0 0 0 0</pose>
      <inertial>
        <mass>0.028148670176164552</mass>
        <inertia>
          <ixx>3.518583772020569e-07</ixx>
          <ixy>0</ixy>
          <ixz>0</ixz>
          <iyy>3.929085212089636e-06</iyy>
          <iyz>0</iyz>
          <izz>3.929085212089636e-06</izz>
        </inertia>
      </inertial>
      <collision name="link_45_collision">
        <geometry>
          <box>
            <size>0.04 0.01 0.01</size>
          </box>
        </geometry>
      </collision>
      <visual name="link_45_visual">
        <geometry>
          <box>
            <size>0.04 0.01 0.01</size>
          </box>
        </geometry>
      </visual>
    </link>
    <joint type="ball" name="joint_44_45">
      <pose>-0.02 0 0 0 0 0</pose>
      <child>link_45</child>
      <parent>link_44</parent>
      <axis>
        <dynamics>
          <damping>10</damping>
          <friction>5</friction>
        </dynamics>
      </axis>
      <axis>
        <dynamics>
          <damping>10</damping>
          <friction>5</friction>
        </dynamics>
      </axis>
    </joint>
    <link name="link_46">
      <gravity>true</gravity>
      <pose>1.84 0 0 0 0 0</pose>
      <inertial>
        <mass>0.028148670176164552</mass>
        <inertia>
          <ixx>3.518583772020569e-07</ixx>
          <ixy>0</ixy>
          <ixz>0</ixz>
          <iyy>3.929085212089636e-06</iyy>
          <iyz>0</iyz>
          <izz>3.929085212089636e-06</izz>
        </inertia>
      </inertial>
      <collision name="link_46_collision">
        <geometry>
          <box>
            <size>0.04 0.01 0.01</size>
          </box>
        </geometry>
      </collision>
      <visual name="link_46_visual">
        <geometry>
          <box>
            <size>0.04 0.01 0.01</size>
          </box>
        </geometry>
      </visual>
    </link>
    <joint type="ball" name="joint_45_46">
      <pose>-0.02 0 0 0 0 0</pose>
      <child>link_46</child>
      <parent>link_45</parent>
      <axis>
        <dynamics>
          <damping>10</damping>
          <friction>5</friction>
        </dynamics>
      </axis>
      <axis>
        <dynamics>
          <damping>10</damping>
          <friction>5</friction>
        </dynamics>
      </axis>
    </joint>
    <link name="link_47">
      <gravity>true</gravity>
      <pose>1.8800000000000001 0 0 0 0 0</pose>
      <inertial>
        <mass>0.028148670176164552</mass>
        <inertia>
          <ixx>3.518583772020569e-07</ixx>
          <ixy>0</ixy>
          <ixz>0</ixz>
          <iyy>3.929085212089636e-06</iyy>
          <iyz>0</iyz>
          <izz>3.929085212089636e-06</izz>
        </inertia>
      </inertial>
      <collision name="link_47_collision">
        <geometry>
          <box>
            <size>0.04 0.01 0.01</size>
          </box>
        </geometry>
      </collision>
      <visual name="link_47_visual">
        <geometry>
          <box>
            <size>0.04 0.01 0.01</size>
          </box>
        </geometry>
      </visual>
    </link>
    <joint type="ball" name="joint_46_47">
      <pose>-0.02 0 0 0 0 0</pose>
      <child>link_47</child>
      <parent>link_46</parent>
      <axis>
        <dynamics>
          <damping>10</damping>
          <friction>5</friction>
        </dynamics>
      </axis>
      <axis>
        <dynamics>
          <damping>10</damping>
          <friction>5</friction>
        </dynamics>
      </axis>
    </joint>
    <link name="link_48">
      <gravity>true</gravity>
      <pose>1.92 0 0 0 0 0</pose>
      <inertial>
        <mass>0.028148670176164552</mass>
        <inertia>
          <ixx>3.518583772020569e-07</ixx>
          <ixy>0</ixy>
          <ixz>0</ixz>
          <iyy>3.929085212089636e-06</iyy>
          <iyz>0</iyz>
          <izz>3.929085212089636e-06</izz>
        </inertia>
      </inertial>
      <collision name="link_48_collision">
        <geometry>
          <box>
            <size>0.04 0.01 0.01</size>
          </box>
        </geometry>
      </collision>
      <visual name="link_48_visual">
        <geometry>
          <box>
            <size>0.04 0.01 0.01</size>
          </box>
        </geometry>
      </visual>
    </link>
    <joint type="ball" name="joint_47_48">
      <pose>-0.02 0 0 0 0 0</pose>
      <child>link_48</child>
      <parent>link_47</parent>
      <axis>
        <dynamics>
          <damping>10</damping>
          <friction>5</friction>
        </dynamics>
      </axis>
      <axis>
        <dynamics>
          <damping>10</damping>
          <friction>5</friction>
        </dynamics>
      </axis>
    </joint>
    <link name="link_49">
      <gravity>true</gravity>
      <pose>1.96 0 0 0 0 0</pose>
      <inertial>
        <mass>0.028148670176164552</mass>
        <inertia>
          <ixx>3.518583772020569e-07</ixx>
          <ixy>0</ixy>
          <ixz>0</ixz>
          <iyy>3.929085212089636e-06</iyy>
          <iyz>0</iyz>
          <izz>3.929085212089636e-06</izz>
        </inertia>
      </inertial>
      <collision name="link_49_collision">
        <geometry>
          <box>
            <size>0.04 0.01 0.01</size>
          </box>
        </geometry>
      </collision>
      <visual name="link_49_visual">
        <geometry>
          <box>
            <size>0.04 0.01 0.01</size>
          </box>
        </geometry>
      </visual>
    </link>
    <joint type="ball" name="joint_48_49">
      <pose>-0.02 0 0 0 0 0</pose>
      <child>link_49</child>
      <parent>link_48</parent>
      <axis>
        <dynamics>
          <damping>10</damping>
          <friction>5</friction>
        </dynamics>
      </axis>
      <axis>
        <dynamics>
          <damping>10</damping>
          <friction>5</friction>
        </dynamics>
      </axis>
    </joint>
  </model>
</sdf>